<?xml version="1.0" ?>
<robot name="rb1_robot">
    <gazebo reference="front_caster_wheel">
        <material>Gazebo/Grey</material>
    </gazebo>
    <gazebo reference="back_caster_wheel">
        <material>Gazebo/Grey</material>
    </gazebo>
    <gazebo reference="left_wheel">
        <material>Gazebo/Grey</material>
    </gazebo>
    <gazebo reference="right_wheel">
        <material>Gazebo/Grey</material>
    </gazebo>

  <!-- Base footprint link -->
  <link name="base_footprint">
  </link>

  <!-- Base link -->
  <gazebo reference="base_link">
        <material>Gazebo/Black</material>
  </gazebo>
  <link name="base_link">
    <inertial>
      <mass value="25" />
      <origin xyz="0 0 0.15" rpy="0 0 0" />
      <!-- Moment of inertia for a solid cylinder -->
      <inertia ixx="0.91145" 
           iyy="0.91145"
           izz="0.78125"
           ixy="0" ixz="0" iyz="0" />
    </inertial>
    <visual>
      <origin xyz="0 0 0" rpy="0 0 0" />
      <geometry>
        <cylinder radius="0.25" length="0.30" />
      </geometry>
      <material name="blue">
        <color rgba="0 0.1 0.8 0.6"/>
      </material>
    </visual>
    <collision>
      <origin xyz="0 0 0" rpy="0 0 0" />
      <geometry>
        <cylinder radius="0.25" length="0.30" />
      </geometry>
    </collision>
  </link>

  <joint name="base_footprint_to_base_link" type="fixed">
    <parent link="base_footprint"/>
    <child link="base_link"/>
    <origin xyz="0 0 0.15" rpy="0 0 0"/>
  </joint>

  <!-- Right wheel joint -->
    <joint name="right_wheel_joint" type="continuous">
        <parent link="base_link"/>
        <child link="right_wheel"/>
        <origin xyz="0.0 -0.2 -0.15" rpy="1.57 0 0"/>
        <axis xyz="0 0 -1"/>
        <dynamics friction="0.02" damping="0.005"/>
    </joint>
    <link name="right_wheel">
        <inertial>
            <mass value="0.5"/>
            <origin xyz="0 0 0" rpy="0 0 0"/>
            <inertia ixx="0.001" iyy="0.001" izz="0.001" ixy="0" ixz="0" iyz="0"/>
        </inertial>
        <visual>
            <origin xyz="0 0 0" rpy="0 0 0" />
            <geometry>
            <cylinder radius="0.025" length="0.02"/>
            </geometry>
            <material name="gray">
                <color rgba="0.8 0.8 0.8 1.0"/>
            </material>
        </visual>
        <collision>
            <origin xyz="0 0 0" rpy="0 0 0" />
            <geometry>
                <cylinder radius="0.025" length="0.02"/>
            </geometry>
        </collision>
    </link>

    <!-- Left wheel joint -->
    <joint name="left_wheel_joint" type="continuous">
        <parent link="base_link"/>
        <child link="left_wheel"/>
        <origin xyz="0.0 0.2 -0.15" rpy="1.57 0 0"/>
        <axis xyz="0 0 -1"/>
        <dynamics friction="0.02" damping="0.005"/>
    </joint>
    <!-- Left wheel -->
    <link name="left_wheel">
        <inertial>
            <mass value="0.5"/>
            <origin xyz="0 0 0" rpy="0 0 0"/>
            <inertia ixx="0.001" iyy="0.001" izz="0.001" ixy="0" ixz="0" iyz="0"/>
        </inertial>
        <visual>
            <origin xyz="0 0 0" rpy="0 0 0" />
            <geometry>
                <cylinder radius="0.025" length="0.02"/>
            </geometry>
            <material name="grey">
                <color rgba="0.8 0.8 0.8 1.0"/>
            </material>
        </visual>
        <collision>
            <origin xyz="0 0 0" rpy="0 0 0" />
            <geometry>
                <cylinder radius="0.025" length="0.02"/>
            </geometry>
        </collision>
    </link>

    <!-- Back caster wheel joint -->
    <joint name="back_caster_joint" type="revolute">
        <parent link="base_link"/>
        <child link="back_caster"/>
        <origin xyz="-0.1 0.0 -0.15" rpy="0 0 0"/>
        <axis xyz="0 0 1"/> <!-- Rotation around the Z-axis -->
        <limit effort="0.0" velocity="0.0" lower="-3.1416" upper="3.1416"/>
    </joint>

    <!-- Back caster wheel -->
    <link name="back_caster">
        <inertial>
            <mass value="0.2"/>
            <origin xyz="0 0 0" rpy="0 0 0"/>
            <inertia ixx="0.001" iyy="0.001" izz="0.001" ixy="0" ixz="0" iyz="0"/>
        </inertial>
        <visual>
            <origin xyz="0 0 0" rpy="0 0 0" />
            <geometry>
                <sphere radius="0.025"/>
            </geometry>
            <material name="gray">
                <color rgba="0.8 0.8 0.8 1.0"/>
            </material>
        </visual>
        <collision>
            <origin xyz="0 0 0" rpy="0 0 0" />
            <geometry>
                <sphere radius="0.025"/>
            </geometry>
        </collision>
        <surface>
            <friction>
                <ode>
                    <mu>0.0</mu>
                    <mu2>0.0</mu2>
                </ode>
            </friction>
        </surface>
    </link>

    <!-- Front caster wheel joint -->
    <joint name="front_caster_joint" type="revolute">
        <parent link="base_link"/>
        <child link="front_caster"/>
        <origin xyz="0.1 0.0 -0.15" rpy="0 0 0"/>
        <axis xyz="0 0 1"/>
        <limit effort="0.0" velocity="0.0" lower="-3.1416" upper="3.1416"/>
    </joint>

    <!-- Front caster wheel -->
    <link name="front_caster">
        <inertial>
            <mass value="0.2"/>
            <origin xyz="0 0 0" rpy="0 0 0"/>
            <inertia ixx="0.001" iyy="0.001" izz="0.001" ixy="0" ixz="0" iyz="0"/>
        </inertial>
        <visual>
            <origin xyz="0 0 0" rpy="0 0 0" />
            <geometry>
                <sphere radius="0.025"/>
            </geometry>
            <material name="gray">
                <color rgba="0.8 0.8 0.8 1.0"/>
            </material>
        </visual>
    <collision>
        <origin xyz="0 0 0" rpy="0 0 0" />
        <geometry>
            <sphere radius="0.025"/>
        </geometry>
        <surface>
        <friction>
            <ode>
                <mu>0.0</mu>
                <mu2>0.0</mu2>
            </ode>
        </friction>
    </surface>
    </collision>
    </link>

    <gazebo>
        <plugin filename="libgazebo_ros_diff_drive.so" name="differential_drive_controller">
            <alwaysOn>true</alwaysOn>
            <updateRate>20</updateRate>
            <leftJoint>left_wheel_joint</leftJoint>
            <rightJoint>right_wheel_joint</rightJoint>
            <wheelSeparation>0.4</wheelSeparation>
            <wheelDiameter>0.05</wheelDiameter>
            <torque>10</torque>
            <commandTopic>cmd_vel</commandTopic>
            <odometryTopic>odom</odometryTopic>
            <odometryFrame>odom</odometryFrame>
            <robotBaseFrame>base_link</robotBaseFrame>
        </plugin>
    </gazebo>

    <!-- Front laser joint -->
    <joint name="front_laser_joint" type="fixed">
        <parent link="base_link"/>
        <child link="front_laser"/>
        <origin xyz="0.25 0.0 0.075" rpy="3.14159 0 0"/>
        <joint_properties damping="1.0" friction="1.0" />
    </joint>

    <!-- Front laser link -->
    <link name="front_laser">
    <inertial>
        <origin xyz="0 0 0" rpy="0 0 0" />
        <mass value="0.5" />
        <inertia ixx="0.000252666666667" ixy="0" ixz="0" iyy="0.000252666666667" iyz="0" izz="0.0005"/>
    </inertial>
    
    <visual>
        <origin xyz="0 0 0" rpy="0 0 0" />
        <geometry>
            <cylinder radius="0.05" length="0.07"/>
        </geometry>
        <material name="Red">
            <color rgba="0.7 0.1 0.1 1" />
        </material>
    </visual>
    <collision>
        <origin xyz="0 0 0" rpy="0 0 0"/>
        <geometry>
            <cylinder radius="0.05" length="0.07"/>
        </geometry>
    </collision>
    </link>
    <!-- Gazebo tags - Laser scan -->
    <gazebo reference="front_laser_joint">
        <preserveFixedJoint>true</preserveFixedJoint>
    </gazebo>
    <gazebo reference="front_laser">
        <material>Gazebo/DarkGrey</material>
    </gazebo>

    <gazebo reference="front_laser">
        <sensor type="ray" name="head_hokuyo_sensor">
            <pose>0 0 0 0 0 0</pose>
            <visualize>true</visualize>
            <update_rate>20</update_rate>
            <ray>
                <scan>
                    <horizontal>
                        <samples>720</samples>
                        <resolution>1</resolution>
                        <min_angle>-1.570796</min_angle>
                        <max_angle>1.570796</max_angle>
                    </horizontal>
                </scan>
                <range>
                    <min>0.13</min>
                    <max>10.0</max>
                    <resolution>0.01</resolution>
                </range>
                <noise>
                    <type>gaussian</type>
                    <mean>0.0</mean>
                    <stddev>0.01</stddev>
                </noise>
            </ray>
            <plugin name="gazebo_ros_head_hokuyo_controller" filename="libgazebo_ros_laser.so">
                <topicName>/scan</topicName>
                <frameName>sensor_laser</frameName>
            </plugin>
        </sensor>
    </gazebo>

</robot>